============================= test session starts ==============================
platform linux -- Python 3.9.2, pytest-6.2.2, py-1.10.0, pluggy-0.13.1
rootdir: /home/stidsem4/iut/2021/controle/lyazid.sellami/c16_03
collected 7 items

test_16_03.py F..FFF.                                                    [100%]

=================================== FAILURES ===================================
_____________________________ Test1603sute.test_10 _____________________________

self = <c16_03.test_16_03.Test1603sute testMethod=test_10>

    def test_10(self):
        try:
            from .main  import Note
        except:
           assert False
        try:
            Note.vider()
        except:
            assert False
        note1 = Note('elv1', 'xx', 12)
        note1 = Note('elv1', 'yy', 13)
        note1 = Note('elv1', 'yy', 14)
        note1 = Note('elv2', 'zz', 13)
        try:
>           assert Note.moyenne('elv1') == 13
E           TypeError: moyenne() takes 1 positional argument but 2 were given

test_16_03.py:106: TypeError

During handling of the above exception, another exception occurred:

self = <c16_03.test_16_03.Test1603sute testMethod=test_10>

    def test_10(self):
        try:
            from .main  import Note
        except:
           assert False
        try:
            Note.vider()
        except:
            assert False
        note1 = Note('elv1', 'xx', 12)
        note1 = Note('elv1', 'yy', 13)
        note1 = Note('elv1', 'yy', 14)
        note1 = Note('elv2', 'zz', 13)
        try:
            assert Note.moyenne('elv1') == 13
    
            assert Note.moyenne('elv1', 'yy') == 13.5
        except TypeError as err:
            if 'argument' in err.args[0]:
>               assert False, 'Probleme de parametres'
E               AssertionError: Probleme de parametres
E               assert False

test_16_03.py:111: AssertionError
----------------------------- Captured stdout call -----------------------------
[13, 15, 13, 12, 13, 12]
Moyenne générale de l'élève 1 : 13.0
La moyenne e l'élève 1 en math est  12.666666666666666
eleve1
maths
13
eleve eleve1 matiere maths note 13
_____________________________ Test1603sute.test_5 ______________________________

self = <c16_03.test_16_03.Test1603sute testMethod=test_5>

    def test_5(self):
        try:
>           from .main  import Note, onotes
E           ImportError: cannot import name 'onotes' from 'c16_03.main' (/home/stidsem4/iut/2021/controle/lyazid.sellami/c16_03/main.py)

test_16_03.py:33: ImportError

During handling of the above exception, another exception occurred:

self = <c16_03.test_16_03.Test1603sute testMethod=test_5>

    def test_5(self):
        try:
            from .main  import Note, onotes
        except:
>           assert False
E           AssertionError: assert False

test_16_03.py:35: AssertionError
_____________________________ Test1603sute.test_6 ______________________________

self = <c16_03.test_16_03.Test1603sute testMethod=test_6>

    def test_6(self):
>       from .main import Note, onotes
E       ImportError: cannot import name 'onotes' from 'c16_03.main' (/home/stidsem4/iut/2021/controle/lyazid.sellami/c16_03/main.py)

test_16_03.py:41: ImportError
_____________________________ Test1603sute.test_8 ______________________________

self = <c16_03.test_16_03.Test1603sute testMethod=test_8>

    def test_8(self):
        try:
            from .main import Note
        except ImportError:
            assert False, "import de Note impossible"
        try:
>           from .main  import moyenne_Notes as mnotes
E           ImportError: cannot import name 'moyenne_Notes' from 'c16_03.main' (/home/stidsem4/iut/2021/controle/lyazid.sellami/c16_03/main.py)

test_16_03.py:71: ImportError

During handling of the above exception, another exception occurred:

self = <c16_03.test_16_03.Test1603sute testMethod=test_8>

    def test_8(self):
        try:
            from .main import Note
        except ImportError:
            assert False, "import de Note impossible"
        try:
            from .main  import moyenne_Notes as mnotes
        except ImportError:
            try:
>               from .main  import moyenne_notes as mnotes
E               ImportError: cannot import name 'moyenne_notes' from 'c16_03.main' (/home/stidsem4/iut/2021/controle/lyazid.sellami/c16_03/main.py)

test_16_03.py:74: ImportError

During handling of the above exception, another exception occurred:

self = <c16_03.test_16_03.Test1603sute testMethod=test_8>

    def test_8(self):
        try:
            from .main import Note
        except ImportError:
            assert False, "import de Note impossible"
        try:
            from .main  import moyenne_Notes as mnotes
        except ImportError:
            try:
                from .main  import moyenne_notes as mnotes
            except ImportError:
>               assert False, "La fonction moyenne_notes n'est pas définie"
E               AssertionError: La fonction moyenne_notes n'est pas définie
E               assert False

test_16_03.py:76: AssertionError
=========================== short test summary info ============================
FAILED test_16_03.py::Test1603sute::test_10 - AssertionError: Probleme de par...
FAILED test_16_03.py::Test1603sute::test_5 - AssertionError: assert False
FAILED test_16_03.py::Test1603sute::test_6 - ImportError: cannot import name ...
FAILED test_16_03.py::Test1603sute::test_8 - AssertionError: La fonction moye...
========================= 4 failed, 3 passed in 0.06s ==========================
